Workbook

Sheet HuongDan
B1: SIXDO – Dashboard đo lường Amazon US (01/10/2026 – 31/03/2027)
B3: Mục đích
B4: Theo dõi chuỗi Traffic → CTR → CVR → Orders → Revenue, cùng duy trì doanh số, sell-through 110 units và khách mới. Đi kèm báo cáo Yêu cầu 06.
B5: Cách dùng mỗi tháng (ngày 1–3 của tháng sau)
B6: 1. Mở sheet NhapLieu, điền các ô nền vàng chữ xanh cho tháng vừa qua, mỗi SKU một dòng. Nguồn từng cột ghi ở dòng tiêu đề.
B7: 2. Mở sheet Dashboard, chọn tháng ở ô C3. Các chỉ số, trạng thái và biểu đồ tự cập nhật.
B8: 3. Đối chiếu cột "Trạng thái" với quy tắc quyết định trong báo cáo Yêu cầu 06 mục 6 và Yêu cầu 02 mục 1.4.
B9: Quy ước màu
B10: Chữ xanh trên nền vàng: ô nhập tay. Chữ đen: công thức. Chữ xanh lá: lấy từ sheet khác. Không sửa ô công thức.
B11: Trạng thái: "Đạt" (xanh) · "Theo dõi" (vàng) · "Cảnh báo" (đỏ). Ngưỡng nằm ở sheet ThamSo.
B12: Các sheet
B13: ThamSo: baseline, giá, tồn đầu kỳ, ngưỡng cảnh báo. KeHoach: kế hoạch theo tháng, kịch bản cơ sở (71 units) và mục tiêu (110 units), tính từ Yêu cầu 02.
... B17: Kế hoạch là giả định [GĐ] và sẽ được thay bằng baseline thật sau 07/10/2026 (sheet ThamSo, ô C4).

Sheet ThamSo
B1: Tham số và ngưỡng
B3: Tham số | C3: Giá trị | D3: Nguồn / ghi chú
B4: Unit Session % baseline | C4: 0.06 | D4: [GĐ] YC02; thay bằng Business Report 90 ngày trước 01/10
B5: CVR traffic ngoài sàn | C5: 0.04 | D5: [GĐ] YC02 kịch bản cơ sở
B6: Giá niêm yết SP1, SP2 (USD) | C6: 51.99 | D6: [XN] đề bài
B7: Giá niêm yết SP3 (USD) | C7: 25.99 | D7: [XN] đề bài
B8: Mục tiêu uplift CVR (lần baseline) | C8: 1.5 | D8: Đề bài: uplift CVR 50%
B9: Ngưỡng "Đạt": % kế hoạch units | C9: 0.9 | D9: Nội bộ
B10: Ngưỡng "Cảnh báo": % kế hoạch units dưới | C10: 0.7 | D10: Nội bộ
B11: Giá bán TB tối thiểu (% niêm yết) | C11: 0.95 | D11: YC02 KPI giữ giá
B12: ACoS tối đa SP1, SP2 (hòa vốn B) | C12: 0.461 | D12: YC02 mục 5
B13: ACoS tối đa SP3 (hòa vốn B) | C13: 0.365 | D13: YC02 mục 5
B14: Tỷ lệ hoàn tối đa | C14: 0.2 | D14: YC02 KPI chất lượng
B15: Rating tối thiểu | C15: 4.3 | D15: YC02 KPI chất lượng
B16: CTR tìm kiếm tối thiểu (SQP) | C16: 0.004 | D16: [GĐ] mốc tạm; thay bằng CTR tháng 10 thực tế
B19: Tồn đầu kỳ theo SKU | C19: Units | D19: Nguồn
B20: SP1 | C20: 20 | D20: [GĐ] YC02; thay bằng Manage FBA Inventory 01/10
B21: SP2 xanh | C21: 20 | D21: [GĐ] YC02; thay bằng Manage FBA Inventory 01/10
B22: SP2 vàng | C22: 20 | D22: [GĐ] YC02; thay bằng Manage FBA Inventory 01/10
B23: SP3 đen | C23: 25 | D23: [GĐ] YC02; thay bằng Manage FBA Inventory 01/10
B24: SP3 hồng | C24: 25 | D24: [GĐ] YC02; thay bằng Manage FBA Inventory 01/10
B25: Tổng | C25: =SUM(C20:C24)
B27: Danh sách tháng
B28: T10
B29: T11
B30: T12
B31: T1
B32: T2
B33: T3

Sheet KeHoach
B1: Kế hoạch theo tháng (tính từ Yêu cầu 02)
B2: Units = (sessions tự nhiên + click PPC) × Unit Session % + click ngoài sàn × CVR ngoài sàn. Ô chữ xanh là giả định [GĐ], sửa được.
B4: Kịch bản cơ sở (71 units) | C4: T10 | D4: T11 | E4: T12 | F4: T1 | G4: T2 | H4: T3 | I4: Tổng | J4: Nguồn
B5: Sessions tự nhiên | C5: 95 | D5: 120 | E5: 120 | F5: 115 | G5: 100 | H5: 105 | I5: =SUM(C5:H5) | J5: YC02 mục 1.3 (cơ sở 655; mục tiêu 922)
B6: Click PPC | C6: 33.3 | D6: 44 | E6: 34.5 | F6: 68.9 | G6: 31.1 | H6: 21.8 | I6: =SUM(C6:H6) | J6: YC02 bảng lịch PPC (234 click)
B7: Click ngoài sàn | C7: 10 | D7: 20 | E7: 10 | F7: 25 | G7: 35 | H7: 20 | I7: =SUM(C7:H7) | J7: YC02, YC04 (cơ sở 120; mục tiêu 150)
B8: Unit Session % (Amazon) | C8: 0.06 | D8: 0.065 | E8: 0.075 | F8: 0.075 | G8: 0.085 | H8: 0.09 | J8: Cơ sở tăng dần 6% → 9%; mục tiêu 9% cả kỳ
B9: Chi PPC (USD) | C9: 30 | D9: 30 | E9: 19 | F9: 62 | G9: 28 | H9: 12 | I9: =SUM(C9:H9) | J9: YC02 mục 9
B10: Tỷ trọng units SP1, SP2 | C10: 0.7 | D10: 0.54 | E10: 0.33 | F10: 0.73 | G10: 0.64 | H10: 0.6 | J10: YC02, cơ cấu SKU theo tháng
B11: Tỷ lệ units từ truy vấn theo dịp | C11: 0.2 | D11: 0.25 | E11: 0.3 | F11: 0.4 | G11: 0.45 | H11: 0.5 | J11: YC02 KPI: 20% → 50%
B12: Sessions tổng | C12: =C5+C6+C7 | D12: =D5+D6+D7 | E12: =E5+E6+E7 | F12: =F5+F6+F7 | G12: =G5+G6+G7 | H12: =H5+H6+H7 | I12: =SUM(C12:H12)
B13: Units kế hoạch | C13: =ROUND((C5+C6)*C8+C7*ThamSo!$C$5,0) | D13: =ROUND((D5+D6)*D8+D7*ThamSo!$C$5,0) | E13: =ROUND((E5+E6)*E8+E7*ThamSo!$C$5,0) | F13: =ROUND((F5+F6)*F8+F7*ThamSo!$C$5,0) | G13: =ROUND((G5+G6)*G8+G7*ThamSo!$C$5,0) | H13: =ROUND((H5+H6)*H8+H7*ThamSo!$C$5,0) | I13: =SUM(C13:H13)
B14: Units lũy kế | C14: =C13 | D14: =C14+D13 | E14: =D14+E13 | F14: =E14+F13 | G14: =F14+G13 | H14: =G14+H13
B15: Sell-through lũy kế (% của tồn đầu kỳ) | C15: =C14/ThamSo!$C$25 | D15: =D14/ThamSo!$C$25 | E15: =E14/ThamSo!$C$25 | F15: =F14/ThamSo!$C$25 | G15: =G14/ThamSo!$C$25 | H15: =H14/ThamSo!$C$25
B16: Doanh số theo giá niêm yết (USD) | C16: =C13*(C10*ThamSo!$C$6+(1-C10)*ThamSo!$C$7) | D16: =D13*(D10*ThamSo!$C$6+(1-D10)*ThamSo!$C$7) | E16: =E13*(E10*ThamSo!$C$6+(1-E10)*ThamSo!$C$7) | F16: =F13*(F10*ThamSo!$C$6+(1-F10)*ThamSo!$C$7) | G16: =G13*(G10*ThamSo!$C$6+(1-G10)*ThamSo!$C$7) | H16: =H13*(H10*ThamSo!$C$6+(1-H10)*ThamSo!$C$7) | I16: =SUM(C16:H16)
B19: Kịch bản mục tiêu (110 units) | C19: T10 | D19: T11 | E19: T12 | F19: T1 | G19: T2 | H19: T3 | I19: Tổng | J19: Nguồn
B20: Sessions tự nhiên | C20: 134 | D20: 169 | E20: 169 | F20: 162 | G20: 141 | H20: 148 | I20: =SUM(C20:H20) | J20: YC02 mục 1.3 (cơ sở 655; mục tiêu 922)
B21: Click PPC | C21: 33.3 | D21: 44 | E21: 34.5 | F21: 68.9 | G21: 31.1 | H21: 21.8 | I21: =SUM(C21:H21) | J21: YC02 bảng lịch PPC (234 click)
B22: Click ngoài sàn | C22: 12 | D22: 25 | E22: 12 | F22: 31 | G22: 45 | H22: 25 | I22: =SUM(C22:H22) | J22: YC02, YC04 (cơ sở 120; mục tiêu 150)
B23: Unit Session % (Amazon) | C23: 0.09 | D23: 0.09 | E23: 0.09 | F23: 0.09 | G23: 0.09 | H23: 0.09 | J23: Cơ sở tăng dần 6% → 9%; mục tiêu 9% cả kỳ
B24: Chi PPC (USD) | C24: 30 | D24: 30 | E24: 19 | F24: 62 | G24: 28 | H24: 12 | I24: =SUM(C24:H24) | J24: YC02 mục 9
B25: Tỷ trọng units SP1, SP2 | C25: 0.7 | D25: 0.54 | E25: 0.33 | F25: 0.73 | G25: 0.64 | H25: 0.6 | J25: YC02, cơ cấu SKU theo tháng
B26: Tỷ lệ units từ truy vấn theo dịp | C26: 0.2 | D26: 0.25 | E26: 0.3 | F26: 0.4 | G26: 0.45 | H26: 0.5 | J26: YC02 KPI: 20% → 50%
B27: Sessions tổng | C27: =C20+C21+C22 | D27: =D20+D21+D22 | E27: =E20+E21+E22 | F27: =F20+F21+F22 | G27: =G20+G21+G22 | H27: =H20+H21+H22 | I27: =SUM(C27:H27)
B28: Units kế hoạch | C28: =ROUND((C20+C21)*C23+C22*ThamSo!$C$5,0) | D28: =ROUND((D20+D21)*D23+D22*ThamSo!$C$5,0) | E28: =ROUND((E20+E21)*E23+E22*ThamSo!$C$5,0) | F28: =ROUND((F20+F21)*F23+F22*ThamSo!$C$5,0) | G28: =ROUND((G20+G21)*G23+G22*ThamSo!$C$5,0) | H28: =ROUND((H20+H21)*H23+H22*ThamSo!$C$5,0) | I28: =SUM(C28:H28)
B29: Units lũy kế | C29: =C28 | D29: =C29+D28 | E29: =D29+E28 | F29: =E29+F28 | G29: =F29+G28 | H29: =G29+H28
B30: Sell-through lũy kế (% của tồn đầu kỳ) | C30: =C29/ThamSo!$C$25 | D30: =D29/ThamSo!$C$25 | E30: =E29/ThamSo!$C$25 | F30: =F29/ThamSo!$C$25 | G30: =G29/ThamSo!$C$25 | H30: =H29/ThamSo!$C$25
B31: Doanh số theo giá niêm yết (USD) | C31: =C28*(C25*ThamSo!$C$6+(1-C25)*ThamSo!$C$7) | D31: =D28*(D25*ThamSo!$C$6+(1-D25)*ThamSo!$C$7) | E31: =E28*(E25*ThamSo!$C$6+(1-E25)*ThamSo!$C$7) | F31: =F28*(F25*ThamSo!$C$6+(1-F25)*ThamSo!$C$7) | G31: =G28*(G25*ThamSo!$C$6+(1-G25)*ThamSo!$C$7) | H31: =H28*(H25*ThamSo!$C$6+(1-H25)*ThamSo!$C$7) | I31: =SUM(C31:H31)

Sheet NhapLieu
A1: Nhập liệu hằng tháng theo SKU
A2: Điền các ô nền vàng chữ xanh. Dòng 4 là VÍ DỤ, không được tính. Cột Q và R là công thức, không sửa.
A3: Tháng | B3: SKU | C3: Impression tìm kiếm (Search Query Performance) | D3: Click tìm kiếm (Search Query Performance) | E3: Sessions tổng (Business Report, ASIN con) | F3: Click PPC (Advertising console) | G3: Click ngoài sàn (Amazon Attribution) | H3: Units bán (Business Report) | I3: Doanh số USD (Ordered product sales) | J3: Chi PPC USD (Advertising console) | K3: Doanh số PPC USD (Advertising console) | L3: Units mua qua ngoài sàn (Amazon Attribution) | M3: Units hoàn (FBA Customer Returns) | N3: Rating cuối tháng (trang sản phẩm) | O3: Units từ truy vấn theo dịp (Search Query Performance) | P3: Units khách mới (Repeat Purchase Behavior) [KC] | Q3: Doanh số theo giá niêm yết (công thức) | R3: Thứ tự tháng (công thức)
A4: VÍ DỤ | B4: SP2 vàng | C4: 1450 | D4: 9 | E4: 58 | F4: 17 | G4: 4 | H4: 4 | I4: 207.96 | J4: 15 | K4: 103.98 | L4: 0 | M4: 0 | N4: 4.4 | O4: 2 | P4: 4
A5: T10 | B5: SP1 | Q5: =H5*IF(LEFT(B5,3)="SP3",ThamSo!$C$7,ThamSo!$C$6) | R5: =MATCH(A5,ThamSo!$B$28:$B$33,0)
A6: T10 | B6: SP2 xanh | Q6: =H6*IF(LEFT(B6,3)="SP3",ThamSo!$C$7,ThamSo!$C$6) | R6: =MATCH(A6,ThamSo!$B$28:$B$33,0)
A7: T10 | B7: SP2 vàng | Q7: =H7*IF(LEFT(B7,3)="SP3",ThamSo!$C$7,ThamSo!$C$6) | R7: =MATCH(A7,ThamSo!$B$28:$B$33,0)
A8: T10 | B8: SP3 đen | Q8: =H8*IF(LEFT(B8,3)="SP3",ThamSo!$C$7,ThamSo!$C$6) | R8: =MATCH(A8,ThamSo!$B$28:$B$33,0)
A9: T10 | B9: SP3 hồng | Q9: =H9*IF(LEFT(B9,3)="SP3",ThamSo!$C$7,ThamSo!$C$6) | R9: =MATCH(A9,ThamSo!$B$28:$B$33,0)
A10: T11 | B10: SP1 | Q10: =H10*IF(LEFT(B10,3)="SP3",ThamSo!$C$7,ThamSo!$C$6) | R10: =MATCH(A10,ThamSo!$B$28:$B$33,0)
A11: T11 | B11: SP2 xanh | Q11: =H11*IF(LEFT(B11,3)="SP3",ThamSo!$C$7,ThamSo!$C$6) | R11: =MATCH(A11,ThamSo!$B$28:$B$33,0)
A12: T11 | B12: SP2 vàng | Q12: =H12*IF(LEFT(B12,3)="SP3",ThamSo!$C$7,ThamSo!$C$6) | R12: =MATCH(A12,ThamSo!$B$28:$B$33,0)
A13: T11 | B13: SP3 đen | Q13: =H13*IF(LEFT(B13,3)="SP3",ThamSo!$C$7,ThamSo!$C$6) | R13: =MATCH(A13,ThamSo!$B$28:$B$33,0)
A14: T11 | B14: SP3 hồng | Q14: =H14*IF(LEFT(B14,3)="SP3",ThamSo!$C$7,ThamSo!$C$6) | R14: =MATCH(A14,ThamSo!$B$28:$B$33,0)
A15: T12 | B15: SP1 | Q15: =H15*IF(LEFT(B15,3)="SP3",ThamSo!$C$7,ThamSo!$C$6) | R15: =MATCH(A15,ThamSo!$B$28:$B$33,0)
A16: T12 | B16: SP2 xanh | Q16: =H16*IF(LEFT(B16,3)="SP3",ThamSo!$C$7,ThamSo!$C$6) | R16: =MATCH(A16,ThamSo!$B$28:$B$33,0)
... A34: T3 | B34: SP3 hồng | Q34: =H34*IF(LEFT(B34,3)="SP3",ThamSo!$C$7,ThamSo!$C$6) | R34: =MATCH(A34,ThamSo!$B$28:$B$33,0)

Sheet Dashboard
B1: SIXDO – Dashboard đo lường
B3: Tháng đang xem | C3: T12 | D3: =MATCH(C3,ThamSo!$B$28:$B$33,0) | E3: ← thứ tự tháng (công thức)
B5: Tổng hợp đến hết tháng đang xem | C5: Thực tế | D5: Cơ sở | E5: Mục tiêu | F5: Trạng thái
B6: Units lũy kế | C6: =SUMIFS(NhapLieu!$H$5:$H$34,NhapLieu!$R$5:$R$34,"<="&$D$3) | D6: =INDEX(KeHoach!$C$14:$H$14,$D$3) | E6: =INDEX(KeHoach!$C$29:$H$29,$D$3) | F6: =IF(C6=0,"-",IF(C6>=D6*ThamSo!$C$9,"Đạt",IF(C6>=D6*ThamSo!$C$10,"Theo dõi","Cảnh báo"))) | K6: So với kịch bản cơ sở
B7: Sell-through lũy kế | C7: =C6/ThamSo!$C$25 | D7: =INDEX(KeHoach!$C$15:$H$15,$D$3) | E7: =INDEX(KeHoach!$C$30:$H$30,$D$3) | F7: =F6 | K7: Đi cùng units lũy kế
B8: Unit Session % lũy kế (sessions Amazon) | C8: =IF(SUMIFS(NhapLieu!$E$5:$E$34,NhapLieu!$R$5:$R$34,"<="&$D$3)-SUMIFS(NhapLieu!$G$5:$G$34,NhapLieu!$R$5:$R$34,"<="&$D$3)=0,0,(C6-SUMIFS(NhapLieu!$L$5:$L$34,NhapLieu!$R$5:$R$34,"<="&$D$3))/(SUMIFS(NhapLieu!$E$5:$E$34,NhapLieu!$R$5:$R$34,"<="&$D$3)-SUMIFS(NhapLieu!$G$5:$G$34,NhapLieu!$R$5:$R$34,"<="&$D$3))) | D8: =INDEX(KeHoach!$C$8:$H$8,$D$3) | E8: =INDEX(KeHoach!$C$23:$H$23,$D$3) | F8: =IF(C8=0,"-",IF(C8>=ThamSo!$C$4*ThamSo!$C$8,"Đạt",IF(C8>=ThamSo!$C$4,"Theo dõi","Cảnh báo"))) | K8: Đạt khi ≥ 1,5 lần baseline
B9: Uplift CVR (lần baseline) | C9: =C8/ThamSo!$C$4 | D9: =D8/ThamSo!$C$4 | E9: =E8/ThamSo!$C$4 | F9: =F8 | K9: Đề bài: ≥ 1,5x
B10: Doanh số lũy kế (USD) | C10: =SUMIFS(NhapLieu!$I$5:$I$34,NhapLieu!$R$5:$R$34,"<="&$D$3) | D10: =SUMPRODUCT((COLUMN(KeHoach!$C$16:$H$16)-2<=$D$3)*KeHoach!$C$16:$H$16) | E10: =SUMPRODUCT((COLUMN(KeHoach!$C$31:$H$31)-2<=$D$3)*KeHoach!$C$31:$H$31) | F10: =IF(C10=0,"-",IF(C10>=D10*ThamSo!$C$9,"Đạt",IF(C10>=D10*ThamSo!$C$10,"Theo dõi","Cảnh báo"))) | K10: Kế hoạch tính theo giá niêm yết
B11: Giá bán TB (% giá niêm yết) | C11: =IF(SUMIFS(NhapLieu!$Q$5:$Q$34,NhapLieu!$R$5:$R$34,"<="&$D$3)=0,0,C10/SUMIFS(NhapLieu!$Q$5:$Q$34,NhapLieu!$R$5:$R$34,"<="&$D$3)) | D11: =ThamSo!$C$11 | E11: =ThamSo!$C$11 | F11: =IF(C11=0,"-",IF(C11>=ThamSo!$C$11,"Đạt","Cảnh báo")) | K11: Giữ giá: ≥ 95%
B14: Theo tháng | C14: T10 | D14: T11 | E14: T12 | F14: T1 | G14: T2 | H14: T3 | I14: Cả kỳ | J14: Trạng thái tháng đang xem | K14: Công thức / nguồn
B15: Impression tìm kiếm | C15: =SUMIFS(NhapLieu!$C$5:$C$34,NhapLieu!$A$5:$A$34,C$14) | D15: =SUMIFS(NhapLieu!$C$5:$C$34,NhapLieu!$A$5:$A$34,D$14) | E15: =SUMIFS(NhapLieu!$C$5:$C$34,NhapLieu!$A$5:$A$34,E$14) | F15: =SUMIFS(NhapLieu!$C$5:$C$34,NhapLieu!$A$5:$A$34,F$14) | G15: =SUMIFS(NhapLieu!$C$5:$C$34,NhapLieu!$A$5:$A$34,G$14) | H15: =SUMIFS(NhapLieu!$C$5:$C$34,NhapLieu!$A$5:$A$34,H$14) | I15: =SUM(C15:H15) | K15: SQP
B16: CTR tìm kiếm | C16: =IF(C15=0,0,SUMIFS(NhapLieu!$D$5:$D$34,NhapLieu!$A$5:$A$34,C$14)/C15) | D16: =IF(D15=0,0,SUMIFS(NhapLieu!$D$5:$D$34,NhapLieu!$A$5:$A$34,D$14)/D15) | E16: =IF(E15=0,0,SUMIFS(NhapLieu!$D$5:$D$34,NhapLieu!$A$5:$A$34,E$14)/E15) | F16: =IF(F15=0,0,SUMIFS(NhapLieu!$D$5:$D$34,NhapLieu!$A$5:$A$34,F$14)/F15) | G16: =IF(G15=0,0,SUMIFS(NhapLieu!$D$5:$D$34,NhapLieu!$A$5:$A$34,G$14)/G15) | H16: =IF(H15=0,0,SUMIFS(NhapLieu!$D$5:$D$34,NhapLieu!$A$5:$A$34,H$14)/H15) | I16: =IF(I15=0,0,SUM(NhapLieu!$D$5:$D$34)/I15) | J16: =IF(INDEX(C16:H16,$D$3)=0,"-",IF(INDEX(C16:H16,$D$3)>=ThamSo!$C$16,"Đạt","Theo dõi")) | K16: Click ÷ impression (SQP)
B17: Sessions tổng | C17: =SUMIFS(NhapLieu!$E$5:$E$34,NhapLieu!$A$5:$A$34,C$14) | D17: =SUMIFS(NhapLieu!$E$5:$E$34,NhapLieu!$A$5:$A$34,D$14) | E17: =SUMIFS(NhapLieu!$E$5:$E$34,NhapLieu!$A$5:$A$34,E$14) | F17: =SUMIFS(NhapLieu!$E$5:$E$34,NhapLieu!$A$5:$A$34,F$14) | G17: =SUMIFS(NhapLieu!$E$5:$E$34,NhapLieu!$A$5:$A$34,G$14) | H17: =SUMIFS(NhapLieu!$E$5:$E$34,NhapLieu!$A$5:$A$34,H$14) | I17: =SUM(C17:H17) | K17: Business Report
B18: Sessions tự nhiên | C18: =C17-C19-C20 | D18: =D17-D19-D20 | E18: =E17-E19-E20 | F18: =F17-F19-F20 | G18: =G17-G19-G20 | H18: =H17-H19-H20 | I18: =SUM(C18:H18) | K18: Tổng − PPC − ngoài sàn
B19: Click PPC | C19: =SUMIFS(NhapLieu!$F$5:$F$34,NhapLieu!$A$5:$A$34,C$14) | D19: =SUMIFS(NhapLieu!$F$5:$F$34,NhapLieu!$A$5:$A$34,D$14) | E19: =SUMIFS(NhapLieu!$F$5:$F$34,NhapLieu!$A$5:$A$34,E$14) | F19: =SUMIFS(NhapLieu!$F$5:$F$34,NhapLieu!$A$5:$A$34,F$14) | G19: =SUMIFS(NhapLieu!$F$5:$F$34,NhapLieu!$A$5:$A$34,G$14) | H19: =SUMIFS(NhapLieu!$F$5:$F$34,NhapLieu!$A$5:$A$34,H$14) | I19: =SUM(C19:H19) | K19: Advertising console
B20: Click ngoài sàn | C20: =SUMIFS(NhapLieu!$G$5:$G$34,NhapLieu!$A$5:$A$34,C$14) | D20: =SUMIFS(NhapLieu!$G$5:$G$34,NhapLieu!$A$5:$A$34,D$14) | E20: =SUMIFS(NhapLieu!$G$5:$G$34,NhapLieu!$A$5:$A$34,E$14) | F20: =SUMIFS(NhapLieu!$G$5:$G$34,NhapLieu!$A$5:$A$34,F$14) | G20: =SUMIFS(NhapLieu!$G$5:$G$34,NhapLieu!$A$5:$A$34,G$14) | H20: =SUMIFS(NhapLieu!$G$5:$G$34,NhapLieu!$A$5:$A$34,H$14) | I20: =SUM(C20:H20) | K20: Amazon Attribution
B21: Unit Session % (sessions Amazon) | C21: =IF(C17-C20=0,0,(C23-SUMIFS(NhapLieu!$L$5:$L$34,NhapLieu!$A$5:$A$34,C$14))/(C17-C20)) | D21: =IF(D17-D20=0,0,(D23-SUMIFS(NhapLieu!$L$5:$L$34,NhapLieu!$A$5:$A$34,D$14))/(D17-D20)) | E21: =IF(E17-E20=0,0,(E23-SUMIFS(NhapLieu!$L$5:$L$34,NhapLieu!$A$5:$A$34,E$14))/(E17-E20)) | F21: =IF(F17-F20=0,0,(F23-SUMIFS(NhapLieu!$L$5:$L$34,NhapLieu!$A$5:$A$34,F$14))/(F17-F20)) | G21: =IF(G17-G20=0,0,(G23-SUMIFS(NhapLieu!$L$5:$L$34,NhapLieu!$A$5:$A$34,G$14))/(G17-G20)) | H21: =IF(H17-H20=0,0,(H23-SUMIFS(NhapLieu!$L$5:$L$34,NhapLieu!$A$5:$A$34,H$14))/(H17-H20)) | I21: =IF(I17-I20=0,0,(I23-I36)/(I17-I20)) | J21: =IF(INDEX(C21:H21,$D$3)=0,"-",IF(INDEX(C21:H21,$D$3)>=ThamSo!$C$4*ThamSo!$C$8,"Đạt",IF(INDEX(C21:H21,$D$3)>=ThamSo!$C$4,"Theo dõi","Cảnh báo"))) | K21: (Units − units ngoài sàn) ÷ (sessions − click ngoài sàn)
B22: Uplift CVR (lần baseline) | C22: =C21/ThamSo!$C$4 | D22: =D21/ThamSo!$C$4 | E22: =E21/ThamSo!$C$4 | F22: =F21/ThamSo!$C$4 | G22: =G21/ThamSo!$C$4 | H22: =H21/ThamSo!$C$4 | I22: =I21/ThamSo!$C$4 | J22: =IF(INDEX(C22:H22,$D$3)=0,"-",IF(INDEX(C22:H22,$D$3)>=ThamSo!$C$8,"Đạt",IF(INDEX(C22:H22,$D$3)>=1,"Theo dõi","Cảnh báo"))) | K22: Mục tiêu ≥ 1,5x
B23: Units bán | C23: =SUMIFS(NhapLieu!$H$5:$H$34,NhapLieu!$A$5:$A$34,C$14) | D23: =SUMIFS(NhapLieu!$H$5:$H$34,NhapLieu!$A$5:$A$34,D$14) | E23: =SUMIFS(NhapLieu!$H$5:$H$34,NhapLieu!$A$5:$A$34,E$14) | F23: =SUMIFS(NhapLieu!$H$5:$H$34,NhapLieu!$A$5:$A$34,F$14) | G23: =SUMIFS(NhapLieu!$H$5:$H$34,NhapLieu!$A$5:$A$34,G$14) | H23: =SUMIFS(NhapLieu!$H$5:$H$34,NhapLieu!$A$5:$A$34,H$14) | I23: =SUM(C23:H23) | K23: Business Report
B24: Units kế hoạch (cơ sở) | C24: =KeHoach!C13 | D24: =KeHoach!D13 | E24: =KeHoach!E13 | F24: =KeHoach!F13 | G24: =KeHoach!G13 | H24: =KeHoach!H13 | I24: =SUM(C24:H24) | K24: Sheet KeHoach
B25: % kế hoạch | C25: =IF(C24=0,0,C23/C24) | D25: =IF(D24=0,0,D23/D24) | E25: =IF(E24=0,0,E23/E24) | F25: =IF(F24=0,0,F23/F24) | G25: =IF(G24=0,0,G23/G24) | H25: =IF(H24=0,0,H23/H24) | I25: =IF(I24=0,0,I23/I24) | J25: =IF(INDEX(C25:H25,$D$3)=0,"-",IF(INDEX(C25:H25,$D$3)>=ThamSo!$C$9,"Đạt",IF(INDEX(C25:H25,$D$3)>=ThamSo!$C$10,"Theo dõi","Cảnh báo"))) | K25: Đạt ≥ 90%; cảnh báo < 70%
B26: Sell-through lũy kế | C26: =SUMIFS(NhapLieu!$H$5:$H$34,NhapLieu!$R$5:$R$34,"<="&MATCH(C$14,ThamSo!$B$28:$B$33,0))/ThamSo!$C$25 | D26: =SUMIFS(NhapLieu!$H$5:$H$34,NhapLieu!$R$5:$R$34,"<="&MATCH(D$14,ThamSo!$B$28:$B$33,0))/ThamSo!$C$25 | E26: =SUMIFS(NhapLieu!$H$5:$H$34,NhapLieu!$R$5:$R$34,"<="&MATCH(E$14,ThamSo!$B$28:$B$33,0))/ThamSo!$C$25 | F26: =SUMIFS(NhapLieu!$H$5:$H$34,NhapLieu!$R$5:$R$34,"<="&MATCH(F$14,ThamSo!$B$28:$B$33,0))/ThamSo!$C$25 | G26: =SUMIFS(NhapLieu!$H$5:$H$34,NhapLieu!$R$5:$R$34,"<="&MATCH(G$14,ThamSo!$B$28:$B$33,0))/ThamSo!$C$25 | H26: =SUMIFS(NhapLieu!$H$5:$H$34,NhapLieu!$R$5:$R$34,"<="&MATCH(H$14,ThamSo!$B$28:$B$33,0))/ThamSo!$C$25 | I26: =H26 | K26: Units lũy kế ÷ tồn đầu kỳ
B27: Doanh số (USD) | C27: =SUMIFS(NhapLieu!$I$5:$I$34,NhapLieu!$A$5:$A$34,C$14) | D27: =SUMIFS(NhapLieu!$I$5:$I$34,NhapLieu!$A$5:$A$34,D$14) | E27: =SUMIFS(NhapLieu!$I$5:$I$34,NhapLieu!$A$5:$A$34,E$14) | F27: =SUMIFS(NhapLieu!$I$5:$I$34,NhapLieu!$A$5:$A$34,F$14) | G27: =SUMIFS(NhapLieu!$I$5:$I$34,NhapLieu!$A$5:$A$34,G$14) | H27: =SUMIFS(NhapLieu!$I$5:$I$34,NhapLieu!$A$5:$A$34,H$14) | I27: =SUM(C27:H27) | K27: Ordered product sales
B28: Giá bán TB (% niêm yết) | C28: =IF(SUMIFS(NhapLieu!$Q$5:$Q$34,NhapLieu!$A$5:$A$34,C$14)=0,0,C27/SUMIFS(NhapLieu!$Q$5:$Q$34,NhapLieu!$A$5:$A$34,C$14)) | D28: =IF(SUMIFS(NhapLieu!$Q$5:$Q$34,NhapLieu!$A$5:$A$34,D$14)=0,0,D27/SUMIFS(NhapLieu!$Q$5:$Q$34,NhapLieu!$A$5:$A$34,D$14)) | E28: =IF(SUMIFS(NhapLieu!$Q$5:$Q$34,NhapLieu!$A$5:$A$34,E$14)=0,0,E27/SUMIFS(NhapLieu!$Q$5:$Q$34,NhapLieu!$A$5:$A$34,E$14)) | F28: =IF(SUMIFS(NhapLieu!$Q$5:$Q$34,NhapLieu!$A$5:$A$34,F$14)=0,0,F27/SUMIFS(NhapLieu!$Q$5:$Q$34,NhapLieu!$A$5:$A$34,F$14)) | G28: =IF(SUMIFS(NhapLieu!$Q$5:$Q$34,NhapLieu!$A$5:$A$34,G$14)=0,0,G27/SUMIFS(NhapLieu!$Q$5:$Q$34,NhapLieu!$A$5:$A$34,G$14)) | H28: =IF(SUMIFS(NhapLieu!$Q$5:$Q$34,NhapLieu!$A$5:$A$34,H$14)=0,0,H27/SUMIFS(NhapLieu!$Q$5:$Q$34,NhapLieu!$A$5:$A$34,H$14)) | I28: =IF(SUM(NhapLieu!$Q$5:$Q$34)=0,0,I27/SUM(NhapLieu!$Q$5:$Q$34)) | J28: =IF(INDEX(C28:H28,$D$3)=0,"-",IF(INDEX(C28:H28,$D$3)>=ThamSo!$C$11,"Đạt","Cảnh báo")) | K28: Doanh số ÷ units × giá niêm yết
B29: Chi PPC (USD) | C29: =SUMIFS(NhapLieu!$J$5:$J$34,NhapLieu!$A$5:$A$34,C$14) | D29: =SUMIFS(NhapLieu!$J$5:$J$34,NhapLieu!$A$5:$A$34,D$14) | E29: =SUMIFS(NhapLieu!$J$5:$J$34,NhapLieu!$A$5:$A$34,E$14) | F29: =SUMIFS(NhapLieu!$J$5:$J$34,NhapLieu!$A$5:$A$34,F$14) | G29: =SUMIFS(NhapLieu!$J$5:$J$34,NhapLieu!$A$5:$A$34,G$14) | H29: =SUMIFS(NhapLieu!$J$5:$J$34,NhapLieu!$A$5:$A$34,H$14) | I29: =SUM(C29:H29) | K29: Advertising console
B30: ACoS | C30: =IF(SUMIFS(NhapLieu!$K$5:$K$34,NhapLieu!$A$5:$A$34,C$14)=0,0,C29/SUMIFS(NhapLieu!$K$5:$K$34,NhapLieu!$A$5:$A$34,C$14)) | D30: =IF(SUMIFS(NhapLieu!$K$5:$K$34,NhapLieu!$A$5:$A$34,D$14)=0,0,D29/SUMIFS(NhapLieu!$K$5:$K$34,NhapLieu!$A$5:$A$34,D$14)) | E30: =IF(SUMIFS(NhapLieu!$K$5:$K$34,NhapLieu!$A$5:$A$34,E$14)=0,0,E29/SUMIFS(NhapLieu!$K$5:$K$34,NhapLieu!$A$5:$A$34,E$14)) | F30: =IF(SUMIFS(NhapLieu!$K$5:$K$34,NhapLieu!$A$5:$A$34,F$14)=0,0,F29/SUMIFS(NhapLieu!$K$5:$K$34,NhapLieu!$A$5:$A$34,F$14)) | G30: =IF(SUMIFS(NhapLieu!$K$5:$K$34,NhapLieu!$A$5:$A$34,G$14)=0,0,G29/SUMIFS(NhapLieu!$K$5:$K$34,NhapLieu!$A$5:$A$34,G$14)) | H30: =IF(SUMIFS(NhapLieu!$K$5:$K$34,NhapLieu!$A$5:$A$34,H$14)=0,0,H29/SUMIFS(NhapLieu!$K$5:$K$34,NhapLieu!$A$5:$A$34,H$14)) | I30: =IF(SUM(NhapLieu!$K$5:$K$34)=0,0,I29/SUM(NhapLieu!$K$5:$K$34)) | J30: =IF(INDEX(C30:H30,$D$3)=0,"-",IF(INDEX(C30:H30,$D$3)<=ThamSo!$C$13,"Đạt",IF(INDEX(C30:H30,$D$3)<=ThamSo!$C$12,"Theo dõi","Cảnh báo"))) | K30: Chi PPC ÷ doanh số PPC; so với hòa vốn B
B31: TACoS | C31: =IF(C27=0,0,C29/C27) | D31: =IF(D27=0,0,D29/D27) | E31: =IF(E27=0,0,E29/E27) | F31: =IF(F27=0,0,F29/F27) | G31: =IF(G27=0,0,G29/G27) | H31: =IF(H27=0,0,H29/H27) | I31: =IF(I27=0,0,I29/I27) | K31: Chi PPC ÷ tổng doanh số
B32: Tỷ lệ hoàn | C32: =IF(C23=0,0,SUMIFS(NhapLieu!$M$5:$M$34,NhapLieu!$A$5:$A$34,C$14)/C23) | D32: =IF(D23=0,0,SUMIFS(NhapLieu!$M$5:$M$34,NhapLieu!$A$5:$A$34,D$14)/D23) | E32: =IF(E23=0,0,SUMIFS(NhapLieu!$M$5:$M$34,NhapLieu!$A$5:$A$34,E$14)/E23) | F32: =IF(F23=0,0,SUMIFS(NhapLieu!$M$5:$M$34,NhapLieu!$A$5:$A$34,F$14)/F23) | G32: =IF(G23=0,0,SUMIFS(NhapLieu!$M$5:$M$34,NhapLieu!$A$5:$A$34,G$14)/G23) | H32: =IF(H23=0,0,SUMIFS(NhapLieu!$M$5:$M$34,NhapLieu!$A$5:$A$34,H$14)/H23) | I32: =IF(I23=0,0,SUM(NhapLieu!$M$5:$M$34)/I23) | J32: =IF(INDEX(C23:H23,$D$3)=0,"-",IF(INDEX(C32:H32,$D$3)<=ThamSo!$C$14*0.75,"Đạt",IF(INDEX(C32:H32,$D$3)<=ThamSo!$C$14,"Theo dõi","Cảnh báo"))) | K32: Units hoàn ÷ units bán; tối đa 20%
B33: Rating thấp nhất trong các SKU | C33: =IF(C23=0,0,_xlfn.MINIFS(NhapLieu!$N$5:$N$34,NhapLieu!$A$5:$A$34,C$14,NhapLieu!$N$5:$N$34,">0")) | D33: =IF(D23=0,0,_xlfn.MINIFS(NhapLieu!$N$5:$N$34,NhapLieu!$A$5:$A$34,D$14,NhapLieu!$N$5:$N$34,">0")) | E33: =IF(E23=0,0,_xlfn.MINIFS(NhapLieu!$N$5:$N$34,NhapLieu!$A$5:$A$34,E$14,NhapLieu!$N$5:$N$34,">0")) | F33: =IF(F23=0,0,_xlfn.MINIFS(NhapLieu!$N$5:$N$34,NhapLieu!$A$5:$A$34,F$14,NhapLieu!$N$5:$N$34,">0")) | G33: =IF(G23=0,0,_xlfn.MINIFS(NhapLieu!$N$5:$N$34,NhapLieu!$A$5:$A$34,G$14,NhapLieu!$N$5:$N$34,">0")) | H33: =IF(H23=0,0,_xlfn.MINIFS(NhapLieu!$N$5:$N$34,NhapLieu!$A$5:$A$34,H$14,NhapLieu!$N$5:$N$34,">0")) | I33: =_xlfn.MINIFS(C33:H33,C33:H33,">0") | J33: =IF(INDEX(C33:H33,$D$3)=0,"-",IF(INDEX(C33:H33,$D$3)>=ThamSo!$C$15,"Đạt","Cảnh báo")) | K33: Tối thiểu 4,3
B34: % units từ truy vấn theo dịp | C34: =IF(C23=0,0,SUMIFS(NhapLieu!$O$5:$O$34,NhapLieu!$A$5:$A$34,C$14)/C23) | D34: =IF(D23=0,0,SUMIFS(NhapLieu!$O$5:$O$34,NhapLieu!$A$5:$A$34,D$14)/D23) | E34: =IF(E23=0,0,SUMIFS(NhapLieu!$O$5:$O$34,NhapLieu!$A$5:$A$34,E$14)/E23) | F34: =IF(F23=0,0,SUMIFS(NhapLieu!$O$5:$O$34,NhapLieu!$A$5:$A$34,F$14)/F23) | G34: =IF(G23=0,0,SUMIFS(NhapLieu!$O$5:$O$34,NhapLieu!$A$5:$A$34,G$14)/G23) | H34: =IF(H23=0,0,SUMIFS(NhapLieu!$O$5:$O$34,NhapLieu!$A$5:$A$34,H$14)/H23) | I34: =IF(I23=0,0,SUM(NhapLieu!$O$5:$O$34)/I23) | J34: =IF(INDEX(C23:H23,$D$3)=0,"-",IF(INDEX(C34:H34,$D$3)>=INDEX(KeHoach!$C$11:$H$11,$D$3),"Đạt","Theo dõi")) | K34: Mục tiêu 20% (T10) → 50% (T3)
B35: % units từ khách mới [KC] | C35: =IF(C23=0,0,SUMIFS(NhapLieu!$P$5:$P$34,NhapLieu!$A$5:$A$34,C$14)/C23) | D35: =IF(D23=0,0,SUMIFS(NhapLieu!$P$5:$P$34,NhapLieu!$A$5:$A$34,D$14)/D23) | E35: =IF(E23=0,0,SUMIFS(NhapLieu!$P$5:$P$34,NhapLieu!$A$5:$A$34,E$14)/E23) | F35: =IF(F23=0,0,SUMIFS(NhapLieu!$P$5:$P$34,NhapLieu!$A$5:$A$34,F$14)/F23) | G35: =IF(G23=0,0,SUMIFS(NhapLieu!$P$5:$P$34,NhapLieu!$A$5:$A$34,G$14)/G23) | H35: =IF(H23=0,0,SUMIFS(NhapLieu!$P$5:$P$34,NhapLieu!$A$5:$A$34,H$14)/H23) | I35: =IF(I23=0,0,SUM(NhapLieu!$P$5:$P$34)/I23) | K35: Repeat Purchase Behavior
B36: Units qua ngoài sàn | C36: =SUMIFS(NhapLieu!$L$5:$L$34,NhapLieu!$A$5:$A$34,C$14) | D36: =SUMIFS(NhapLieu!$L$5:$L$34,NhapLieu!$A$5:$A$34,D$14) | E36: =SUMIFS(NhapLieu!$L$5:$L$34,NhapLieu!$A$5:$A$34,E$14) | F36: =SUMIFS(NhapLieu!$L$5:$L$34,NhapLieu!$A$5:$A$34,F$14) | G36: =SUMIFS(NhapLieu!$L$5:$L$34,NhapLieu!$A$5:$A$34,G$14) | H36: =SUMIFS(NhapLieu!$L$5:$L$34,NhapLieu!$A$5:$A$34,H$14) | I36: =SUM(C36:H36) | K36: Amazon Attribution
B39: Tồn kho theo SKU đến hết tháng đang xem
B40: SKU | C40: Tồn đầu kỳ | D40: Units bán lũy kế | E40: Tồn còn lại | F40: Sell-through | G40: Units tháng đang xem | H40: Tháng còn hàng (ước tính) | I40: Việc cần làm
B41: SP1 | C41: =ThamSo!C20 | D41: =SUMIFS(NhapLieu!$H$5:$H$34,NhapLieu!$B$5:$B$34,B41,NhapLieu!$R$5:$R$34,"<="&$D$3) | E41: =C41-D41 | F41: =IF(C41=0,0,D41/C41) | G41: =SUMIFS(NhapLieu!$H$5:$H$34,NhapLieu!$B$5:$B$34,B41,NhapLieu!$A$5:$A$34,$C$3) | H41: =IF(G41=0,"-",E41/G41) | I41: =IF(E41<=1,"Dừng quảng cáo biến thể còn ≤ 1 unit",IF(AND($D$3>=5,E41>2*G41*(7-$D$3)),"Tồn cao: bundle, coupon theo dịp tháng 3","Theo kế hoạch"))
B42: SP2 xanh | C42: =ThamSo!C21 | D42: =SUMIFS(NhapLieu!$H$5:$H$34,NhapLieu!$B$5:$B$34,B42,NhapLieu!$R$5:$R$34,"<="&$D$3) | E42: =C42-D42 | F42: =IF(C42=0,0,D42/C42) | G42: =SUMIFS(NhapLieu!$H$5:$H$34,NhapLieu!$B$5:$B$34,B42,NhapLieu!$A$5:$A$34,$C$3) | H42: =IF(G42=0,"-",E42/G42) | I42: =IF(E42<=1,"Dừng quảng cáo biến thể còn ≤ 1 unit",IF(AND($D$3>=5,E42>2*G42*(7-$D$3)),"Tồn cao: bundle, coupon theo dịp tháng 3","Theo kế hoạch"))
B43: SP2 vàng | C43: =ThamSo!C22 | D43: =SUMIFS(NhapLieu!$H$5:$H$34,NhapLieu!$B$5:$B$34,B43,NhapLieu!$R$5:$R$34,"<="&$D$3) | E43: =C43-D43 | F43: =IF(C43=0,0,D43/C43) | G43: =SUMIFS(NhapLieu!$H$5:$H$34,NhapLieu!$B$5:$B$34,B43,NhapLieu!$A$5:$A$34,$C$3) | H43: =IF(G43=0,"-",E43/G43) | I43: =IF(E43<=1,"Dừng quảng cáo biến thể còn ≤ 1 unit",IF(AND($D$3>=5,E43>2*G43*(7-$D$3)),"Tồn cao: bundle, coupon theo dịp tháng 3","Theo kế hoạch"))
B44: SP3 đen | C44: =ThamSo!C23 | D44: =SUMIFS(NhapLieu!$H$5:$H$34,NhapLieu!$B$5:$B$34,B44,NhapLieu!$R$5:$R$34,"<="&$D$3) | E44: =C44-D44 | F44: =IF(C44=0,0,D44/C44) | G44: =SUMIFS(NhapLieu!$H$5:$H$34,NhapLieu!$B$5:$B$34,B44,NhapLieu!$A$5:$A$34,$C$3) | H44: =IF(G44=0,"-",E44/G44) | I44: =IF(E44<=1,"Dừng quảng cáo biến thể còn ≤ 1 unit",IF(AND($D$3>=5,E44>2*G44*(7-$D$3)),"Tồn cao: bundle, coupon theo dịp tháng 3","Theo kế hoạch"))
B45: SP3 hồng | C45: =ThamSo!C24 | D45: =SUMIFS(NhapLieu!$H$5:$H$34,NhapLieu!$B$5:$B$34,B45,NhapLieu!$R$5:$R$34,"<="&$D$3) | E45: =C45-D45 | F45: =IF(C45=0,0,D45/C45) | G45: =SUMIFS(NhapLieu!$H$5:$H$34,NhapLieu!$B$5:$B$34,B45,NhapLieu!$A$5:$A$34,$C$3) | H45: =IF(G45=0,"-",E45/G45) | I45: =IF(E45<=1,"Dừng quảng cáo biến thể còn ≤ 1 unit",IF(AND($D$3>=5,E45>2*G45*(7-$D$3)),"Tồn cao: bundle, coupon theo dịp tháng 3","Theo kế hoạch"))
B48: Dữ liệu cho biểu đồ | C48: T10 | D48: T11 | E48: T12 | F48: T1 | G48: T2 | H48: T3
...
